Performing system checks...

System check identified no issues (0 silenced).
June 10, 2017 - 06:23:16
Django version 1.9.9, using settings 'mysite.settings'
Starting development server at http://0.0.0.0:8888/
Quit the server with CONTROL-C.
Performing system checks...

System check identified no issues (0 silenced).
June 10, 2017 - 06:24:27
Django version 1.9.9, using settings 'mysite.settings'
Starting development server at http://0.0.0.0:8888/
Quit the server with CONTROL-C.
[10/Jun/2017 06:24:32] "GET /add_rest/5/ HTTP/1.1" 200 882
Internal Server Error: /add_rest/5/
Traceback (most recent call last):
  File "/usr/local/lib/python2.7/dist-packages/django/core/handlers/base.py", line 149, in get_response
    response = self.process_exception_by_middleware(e, request)
  File "/usr/local/lib/python2.7/dist-packages/django/core/handlers/base.py", line 147, in get_response
    response = wrapped_callback(request, *callback_args, **callback_kwargs)
  File "/usr/local/lib/python2.7/dist-packages/ratelimit/decorators.py", line 30, in _wrapped
    return fn(*args, **kw)
  File "/usr/local/lib/python2.7/dist-packages/django/contrib/auth/decorators.py", line 23, in _wrapped_view
    return view_func(request, *args, **kwargs)
  File "/home/ubuntu/finalrebuild/foodvote/views.py", line 166, in add_rest
    group = Group.objects.get(pk=groupterm)
  File "/usr/local/lib/python2.7/dist-packages/django/db/models/manager.py", line 122, in manager_method
    return getattr(self.get_queryset(), name)(*args, **kwargs)
  File "/usr/local/lib/python2.7/dist-packages/django/db/models/query.py", line 381, in get
    num = len(clone)
  File "/usr/local/lib/python2.7/dist-packages/django/db/models/query.py", line 240, in __len__
    self._fetch_all()
  File "/usr/local/lib/python2.7/dist-packages/django/db/models/query.py", line 1074, in _fetch_all
    self._result_cache = list(self.iterator())
  File "/usr/local/lib/python2.7/dist-packages/django/db/models/query.py", line 52, in __iter__
    results = compiler.execute_sql()
  File "/usr/local/lib/python2.7/dist-packages/django/db/models/sql/compiler.py", line 848, in execute_sql
    cursor.execute(sql, params)
  File "/usr/local/lib/python2.7/dist-packages/django/db/backends/utils.py", line 79, in execute
    return super(CursorDebugWrapper, self).execute(sql, params)
  File "/usr/local/lib/python2.7/dist-packages/django/db/backends/utils.py", line 64, in execute
    return self.cursor.execute(sql, params)
  File "/usr/local/lib/python2.7/dist-packages/django/db/utils.py", line 95, in __exit__
    six.reraise(dj_exc_type, dj_exc_value, traceback)
  File "/usr/local/lib/python2.7/dist-packages/django/db/backends/utils.py", line 64, in execute
    return self.cursor.execute(sql, params)
  File "/usr/local/lib/python2.7/dist-packages/django/db/backends/mysql/base.py", line 112, in execute
    return self.cursor.execute(query, args)
  File "/usr/local/lib/python2.7/dist-packages/MySQLdb/cursors.py", line 205, in execute
    self.errorhandler(self, exc, value)
  File "/usr/local/lib/python2.7/dist-packages/MySQLdb/connections.py", line 36, in defaulterrorhandler
    raise errorclass, errorvalue
OperationalError: (1054, "Unknown column 'foodvote_group.location' in 'field list'")
[10/Jun/2017 06:24:36] "POST /add_rest/5/ HTTP/1.1" 500 130724
[10/Jun/2017 06:25:13] "GET /add_rest/5/ HTTP/1.1" 200 882
Internal Server Error: /add_rest/5/
Traceback (most recent call last):
  File "/usr/local/lib/python2.7/dist-packages/django/core/handlers/base.py", line 149, in get_response
    response = self.process_exception_by_middleware(e, request)
  File "/usr/local/lib/python2.7/dist-packages/django/core/handlers/base.py", line 147, in get_response
    response = wrapped_callback(request, *callback_args, **callback_kwargs)
  File "/usr/local/lib/python2.7/dist-packages/ratelimit/decorators.py", line 30, in _wrapped
    return fn(*args, **kw)
  File "/usr/local/lib/python2.7/dist-packages/django/contrib/auth/decorators.py", line 23, in _wrapped_view
    return view_func(request, *args, **kwargs)
  File "/home/ubuntu/finalrebuild/foodvote/views.py", line 170, in add_rest
    return render(request, 'foodvote/addrest.html', {'rg': businesses, 'group': currentgroup})
NameError: global name 'currentgroup' is not defined
[10/Jun/2017 06:25:16] "POST /add_rest/5/ HTTP/1.1" 500 73987
Performing system checks...

System check identified no issues (0 silenced).
June 10, 2017 - 06:24:29
Django version 1.9.9, using settings 'mysite.settings'
Starting development server at http://0.0.0.0:8888/
Quit the server with CONTROL-C.
5
5
[10/Jun/2017 06:25:54] "GET /add_rest/5/ HTTP/1.1" 200 882
Performing system checks...

System check identified no issues (0 silenced).
June 10, 2017 - 06:25:50
Django version 1.9.9, using settings 'mysite.settings'
Starting development server at http://0.0.0.0:8888/
Quit the server with CONTROL-C.
Internal Server Error: /add_rest/5/
Traceback (most recent call last):
  File "/usr/local/lib/python2.7/dist-packages/django/core/handlers/base.py", line 149, in get_response
    response = self.process_exception_by_middleware(e, request)
  File "/usr/local/lib/python2.7/dist-packages/django/core/handlers/base.py", line 147, in get_response
    response = wrapped_callback(request, *callback_args, **callback_kwargs)
  File "/usr/local/lib/python2.7/dist-packages/ratelimit/decorators.py", line 30, in _wrapped
    return fn(*args, **kw)
  File "/usr/local/lib/python2.7/dist-packages/django/contrib/auth/decorators.py", line 23, in _wrapped_view
    return view_func(request, *args, **kwargs)
  File "/home/ubuntu/finalrebuild/foodvote/views.py", line 172, in add_rest
    group = Group.objects.get(pk=groupterm)
UnboundLocalError: local variable 'groupterm' referenced before assignment
[10/Jun/2017 06:27:40] "GET /add_rest/5/ HTTP/1.1" 500 71825
Internal Server Error: /add_rest/5/
Traceback (most recent call last):
  File "/usr/local/lib/python2.7/dist-packages/django/core/handlers/base.py", line 149, in get_response
    response = self.process_exception_by_middleware(e, request)
  File "/usr/local/lib/python2.7/dist-packages/django/core/handlers/base.py", line 147, in get_response
    response = wrapped_callback(request, *callback_args, **callback_kwargs)
  File "/usr/local/lib/python2.7/dist-packages/ratelimit/decorators.py", line 30, in _wrapped
    return fn(*args, **kw)
  File "/usr/local/lib/python2.7/dist-packages/django/contrib/auth/decorators.py", line 23, in _wrapped_view
    return view_func(request, *args, **kwargs)
  File "/home/ubuntu/finalrebuild/foodvote/views.py", line 172, in add_rest
    group = Group.objects.get(pk=groupterm)
UnboundLocalError: local variable 'groupterm' referenced before assignment
[10/Jun/2017 06:27:43] "GET /add_rest/5/ HTTP/1.1" 500 71825
Performing system checks...

System check identified no issues (0 silenced).
June 10, 2017 - 06:27:23
Django version 1.9.9, using settings 'mysite.settings'
Starting development server at http://0.0.0.0:8888/
Quit the server with CONTROL-C.
[10/Jun/2017 06:28:08] "GET /add_rest/5/ HTTP/1.1" 200 886
[10/Jun/2017 06:28:12] "POST /add_rest/5/ HTTP/1.1" 200 5845
Internal Server Error: /add_chose
Traceback (most recent call last):
  File "/usr/local/lib/python2.7/dist-packages/django/core/handlers/base.py", line 149, in get_response
    response = self.process_exception_by_middleware(e, request)
  File "/usr/local/lib/python2.7/dist-packages/django/core/handlers/base.py", line 147, in get_response
    response = wrapped_callback(request, *callback_args, **callback_kwargs)
  File "/usr/local/lib/python2.7/dist-packages/ratelimit/decorators.py", line 30, in _wrapped
    return fn(*args, **kw)
  File "/usr/local/lib/python2.7/dist-packages/django/contrib/auth/decorators.py", line 23, in _wrapped_view
    return view_func(request, *args, **kwargs)
  File "/home/ubuntu/finalrebuild/foodvote/views.py", line 185, in add_chose
    group = Group.objects.get(pk=group_key)
  File "/usr/local/lib/python2.7/dist-packages/django/db/models/manager.py", line 122, in manager_method
    return getattr(self.get_queryset(), name)(*args, **kwargs)
  File "/usr/local/lib/python2.7/dist-packages/django/db/models/query.py", line 387, in get
    self.model._meta.object_name
DoesNotExist: Group matching query does not exist.
[10/Jun/2017 06:28:21] "POST /add_chose HTTP/1.1" 500 81150
[10/Jun/2017 06:30:35] "GET /add_rest/5/ HTTP/1.1" 200 886
[10/Jun/2017 06:30:38] "GET /add_rest/5/ HTTP/1.1" 200 886
[10/Jun/2017 06:30:41] "POST /add_rest/5/ HTTP/1.1" 200 5889
Internal Server Error: /add_chose
Traceback (most recent call last):
  File "/usr/local/lib/python2.7/dist-packages/django/core/handlers/base.py", line 149, in get_response
    response = self.process_exception_by_middleware(e, request)
  File "/usr/local/lib/python2.7/dist-packages/django/core/handlers/base.py", line 147, in get_response
    response = wrapped_callback(request, *callback_args, **callback_kwargs)
  File "/usr/local/lib/python2.7/dist-packages/ratelimit/decorators.py", line 30, in _wrapped
    return fn(*args, **kw)
  File "/usr/local/lib/python2.7/dist-packages/django/contrib/auth/decorators.py", line 23, in _wrapped_view
    return view_func(request, *args, **kwargs)
  File "/home/ubuntu/finalrebuild/foodvote/views.py", line 186, in add_chose
    rgroup_list = Restaurant_Group.objects.filter(Group=group)
  File "/usr/local/lib/python2.7/dist-packages/django/db/models/manager.py", line 122, in manager_method
    return getattr(self.get_queryset(), name)(*args, **kwargs)
  File "/usr/local/lib/python2.7/dist-packages/django/db/models/query.py", line 790, in filter
    return self._filter_or_exclude(False, *args, **kwargs)
  File "/usr/local/lib/python2.7/dist-packages/django/db/models/query.py", line 808, in _filter_or_exclude
    clone.query.add_q(Q(*args, **kwargs))
  File "/usr/local/lib/python2.7/dist-packages/django/db/models/sql/query.py", line 1243, in add_q
    clause, _ = self._add_q(q_object, self.used_aliases)
  File "/usr/local/lib/python2.7/dist-packages/django/db/models/sql/query.py", line 1269, in _add_q
    allow_joins=allow_joins, split_subq=split_subq,
  File "/usr/local/lib/python2.7/dist-packages/django/db/models/sql/query.py", line 1149, in build_filter
    lookups, parts, reffed_expression = self.solve_lookup_type(arg)
  File "/usr/local/lib/python2.7/dist-packages/django/db/models/sql/query.py", line 1035, in solve_lookup_type
    _, field, _, lookup_parts = self.names_to_path(lookup_splitted, self.get_meta())
  File "/usr/local/lib/python2.7/dist-packages/django/db/models/sql/query.py", line 1330, in names_to_path
    "Choices are: %s" % (name, ", ".join(available)))
FieldError: Cannot resolve keyword 'Group' into field. Choices are: group, group_id, hash_field, id, keep, restaurant, restaurant_id, vote
[10/Jun/2017 06:30:54] "POST /add_chose HTTP/1.1" 500 115274
Performing system checks...

System check identified no issues (0 silenced).
June 10, 2017 - 06:28:05
Django version 1.9.9, using settings 'mysite.settings'
Starting development server at http://0.0.0.0:8888/
Quit the server with CONTROL-C.
5
5
[10/Jun/2017 06:31:52] "POST /add_rest/5/ HTTP/1.1" 200 5889
Internal Server Error: /add_chose
Traceback (most recent call last):
  File "/usr/local/lib/python2.7/dist-packages/django/core/handlers/base.py", line 149, in get_response
    response = self.process_exception_by_middleware(e, request)
  File "/usr/local/lib/python2.7/dist-packages/django/core/handlers/base.py", line 147, in get_response
    response = wrapped_callback(request, *callback_args, **callback_kwargs)
  File "/usr/local/lib/python2.7/dist-packages/ratelimit/decorators.py", line 30, in _wrapped
    return fn(*args, **kw)
  File "/usr/local/lib/python2.7/dist-packages/django/contrib/auth/decorators.py", line 23, in _wrapped_view
    return view_func(request, *args, **kwargs)
  File "/home/ubuntu/finalrebuild/foodvote/views.py", line 186, in add_chose
    rgroup_list = Restaurant_Group.objects.filter(Group=group.id)
  File "/usr/local/lib/python2.7/dist-packages/django/db/models/manager.py", line 122, in manager_method
    return getattr(self.get_queryset(), name)(*args, **kwargs)
  File "/usr/local/lib/python2.7/dist-packages/django/db/models/query.py", line 790, in filter
    return self._filter_or_exclude(False, *args, **kwargs)
  File "/usr/local/lib/python2.7/dist-packages/django/db/models/query.py", line 808, in _filter_or_exclude
    clone.query.add_q(Q(*args, **kwargs))
  File "/usr/local/lib/python2.7/dist-packages/django/db/models/sql/query.py", line 1243, in add_q
    clause, _ = self._add_q(q_object, self.used_aliases)
  File "/usr/local/lib/python2.7/dist-packages/django/db/models/sql/query.py", line 1269, in _add_q
    allow_joins=allow_joins, split_subq=split_subq,
  File "/usr/local/lib/python2.7/dist-packages/django/db/models/sql/query.py", line 1149, in build_filter
    lookups, parts, reffed_expression = self.solve_lookup_type(arg)
  File "/usr/local/lib/python2.7/dist-packages/django/db/models/sql/query.py", line 1035, in solve_lookup_type
    _, field, _, lookup_parts = self.names_to_path(lookup_splitted, self.get_meta())
  File "/usr/local/lib/python2.7/dist-packages/django/db/models/sql/query.py", line 1330, in names_to_path
    "Choices are: %s" % (name, ", ".join(available)))
FieldError: Cannot resolve keyword 'Group' into field. Choices are: group, group_id, hash_field, id, keep, restaurant, restaurant_id, vote
[10/Jun/2017 06:31:56] "POST /add_chose HTTP/1.1" 500 115080
Performing system checks...

System check identified no issues (0 silenced).
June 10, 2017 - 06:31:49
Django version 1.9.9, using settings 'mysite.settings'
Starting development server at http://0.0.0.0:8888/
Quit the server with CONTROL-C.
5
[10/Jun/2017 06:32:53] "POST /add_rest/5/ HTTP/1.1" 200 5889
[10/Jun/2017 06:32:57] "POST /add_chose HTTP/1.1" 302 0
[10/Jun/2017 06:32:58] "GET /group_page/5/ HTTP/1.1" 200 8747
[10/Jun/2017 06:34:41] "GET / HTTP/1.1" 200 823
[10/Jun/2017 06:34:42] "GET /find HTTP/1.1" 200 838
[10/Jun/2017 06:34:44] "POST /find HTTP/1.1" 302 0
[10/Jun/2017 06:34:45] "GET /group_list/test/ HTTP/1.1" 200 2223
[10/Jun/2017 06:35:00] "GET /group_page/5/ HTTP/1.1" 200 8747
[10/Jun/2017 06:35:13] "GET / HTTP/1.1" 200 823
[10/Jun/2017 06:35:15] "GET /create HTTP/1.1" 200 1170
[10/Jun/2017 06:35:31] "POST /create HTTP/1.1" 302 0
[10/Jun/2017 06:35:31] "GET /group_page/6/ HTTP/1.1" 200 5960
[10/Jun/2017 06:35:43] "GET / HTTP/1.1" 200 823
[10/Jun/2017 06:46:36] "GET /find HTTP/1.1" 200 838
[10/Jun/2017 06:46:40] "POST /find HTTP/1.1" 302 0
[10/Jun/2017 06:46:40] "GET /group_list/yamish/ HTTP/1.1" 200 908
[10/Jun/2017 06:46:42] "GET /group_page/6/ HTTP/1.1" 200 5960
[10/Jun/2017 06:46:52] "GET /add_rest/6 HTTP/1.1" 301 0
[10/Jun/2017 06:46:52] "GET /add_rest/6/ HTTP/1.1" 200 888
Performing system checks...

System check identified no issues (0 silenced).
June 10, 2017 - 06:32:50
Django version 1.9.9, using settings 'mysite.settings'
Starting development server at http://0.0.0.0:8888/
Quit the server with CONTROL-C.
5
[10/Jun/2017 06:49:05] "GET /add_rest/6/ HTTP/1.1" 200 888
[10/Jun/2017 06:49:09] "GET /add_rest/6/ HTTP/1.1" 200 888
[10/Jun/2017 06:49:10] "GET / HTTP/1.1" 200 823
[10/Jun/2017 06:49:12] "GET /create HTTP/1.1" 200 1170
Internal Server Error: /create
Traceback (most recent call last):
  File "/usr/local/lib/python2.7/dist-packages/django/core/handlers/base.py", line 149, in get_response
    response = self.process_exception_by_middleware(e, request)
  File "/usr/local/lib/python2.7/dist-packages/django/core/handlers/base.py", line 147, in get_response
    response = wrapped_callback(request, *callback_args, **callback_kwargs)
  File "/usr/local/lib/python2.7/dist-packages/ratelimit/decorators.py", line 30, in _wrapped
    return fn(*args, **kw)
  File "/usr/local/lib/python2.7/dist-packages/django/contrib/auth/decorators.py", line 23, in _wrapped_view
    return view_func(request, *args, **kwargs)
  File "/home/ubuntu/finalrebuild/foodvote/views.py", line 125, in create_group
    return render(request, 'foodvote/addrest.html', {'rg': businesses, 'group': group})
NameError: global name 'group' is not defined
[10/Jun/2017 06:49:29] "POST /create HTTP/1.1" 500 74205
Performing system checks...

System check identified no issues (0 silenced).
June 10, 2017 - 06:49:02
Django version 1.9.9, using settings 'mysite.settings'
Starting development server at http://0.0.0.0:8888/
Quit the server with CONTROL-C.
[10/Jun/2017 06:49:51] "POST /create HTTP/1.1" 200 5909
[10/Jun/2017 06:50:06] "POST /add_chose HTTP/1.1" 302 0
[10/Jun/2017 06:50:06] "GET /group_page/8/ HTTP/1.1" 200 3815
[10/Jun/2017 06:50:11] "GET /add_rest/8 HTTP/1.1" 301 0
[10/Jun/2017 06:50:11] "GET /add_rest/8/ HTTP/1.1" 200 889
[10/Jun/2017 06:50:16] "POST /add_rest/8/ HTTP/1.1" 200 5968
[10/Jun/2017 06:50:25] "POST /add_chose HTTP/1.1" 302 0
[10/Jun/2017 06:50:26] "GET /group_page/8/ HTTP/1.1" 200 5858
[10/Jun/2017 06:50:39] "POST /group_page/8/ HTTP/1.1" 302 0
[10/Jun/2017 06:50:39] "GET /result/8/ HTTP/1.1" 200 1325
[10/Jun/2017 06:51:00] "GET / HTTP/1.1" 200 823
Performing system checks...

System check identified no issues (0 silenced).
June 10, 2017 - 06:49:48
Django version 1.9.9, using settings 'mysite.settings'
Starting development server at http://0.0.0.0:8888/
Quit the server with CONTROL-C.
8
